Workbook

Sheet 产品资料
A1: 辅助 | B1: 类别 | C1: 品牌 | D1: 货品名称 | E1: 规格 | F1: 备注 | G1: 6.1报价 | I1: 序号 | J1: 订单类型 | K1: 渠道类别 | L1: 销售渠道 | M1: 业务员 | N1: 订单状态
A2: =D2&E2 -> 联想电脑默认 | B2: 电脑 | C2: 联想 | D2: 联想电脑 | E2: 默认 | G2: / | I2: 1 | J2: 新增业务 | K2: 平台 | L2: A人人租-Z | M2: ZZ | N2: 已发货
A3: =D3&E3 -> HP电脑默认 | B3: 手机 | C3: 惠普 | D3: HP电脑 | E3: 默认 | G3: / | I3: 2 | J3: 租后发货 | K3: 平台 | L3: F人人租-L | M3: LL | N3: 不用发货
A4: =D4&E4 -> IPADAIR2默认 | B4: 手机 | C4: 苹果 | D4: IPADAIR2 | E4: 默认 | G4: 200 | I4: 3 | J4: 租后退货 | K4: 平台 | L4: 云途 | M4: XX | N4: 退货已收
A5: =D5&E5 -> ipadair7默认 | B5: 手机 | C5: 苹果 | D5: ipadair7 | E5: 默认 | G5: / | I5: 4 | J5: 仅退款 | K5: 平台 | L5: 汇租机 | M5: YY | N5: 退发已发
A6: =D6&E6 -> IPADMINI4G | B6: 手机 | C6: 苹果 | D6: IPADMINI | E6: 4G | G6: 200 | I6: 5 | J6: 退租金 | K6: 平台 | L6: 租机乐 | N6: --
A7: =D7&E7 -> IPADMINI5G | B7: 手机 | C7: 苹果 | D7: IPADMINI | E7: 5G | G7: 400 | I7: 6 | J7: 退押金 | K7: 平台 | L7: 倬石电子
A8: =D8&E8 -> IPADMINI默认 | B8: 手机 | C8: 苹果 | D8: IPADMINI | E8: 默认 | G8: 200 | I8: 7 | J8: 委托代发 | K8: 平台 | L8: 云界互联 | M8: --
A9: =D9&E9 -> ipadmini4默认 | B9: 手机 | C9: 苹果 | D9: ipadmini4 | E9: 默认 | G9: 200 | I9: 8 | K9: 平台 | L9: 极客矩阵 | M9: --
A10: =D10&E10 -> ipadmini5默认 | B10: 手机 | C10: 苹果 | D10: ipadmini5 | E10: 默认 | G10: 400 | I10: 9 | K10: 平台 | L10: 极速闪租 | M10: --
A11: =D11&E11 -> ipadpro11默认 | B11: 手机 | C11: 苹果 | D11: ipadpro11 | E11: 默认 | G11: / | I11: 10 | K11: 平台 | L11: L人人租 | M11: --
A12: =D12&E12 -> ipadpro12默认 | B12: 手机 | C12: 苹果 | D12: ipadpro12 | E12: 默认 | G12: / | I12: 11 | K12: 平台 | L12: J人人租 | M12: --
A13: =D13&E13 -> ipadpro9默认 | B13: 手机 | C13: 苹果 | D13: ipadpro9 | E13: 默认 | G13: / | I13: 12 | K13: 平台 | L13: G人人租 | M13: --
A14: =D14&E14 -> IRAD7默认 | B14: 手机 | C14: 苹果 | D14: IRAD7 | E14: 默认 | G14: / | I14: 13 | K14: 线下 | L14: X/A人人租 | M14: ZZ
A15: =D15&E15 -> MOTOX40默认 | B15: 手机 | C15: MOTO | D15: MOTOX40 | E15: 默认 | G15: / | I15: 14 | K15: 线下 | L15: X/F人人租 | M15: LL
A16: =D16&E16 -> OPPO A32默认 | B16: 手机 | C16: OPPO | D16: OPPO A32 | E16: 默认 | G16: / | I16: 15 | K16: 线下 | L16: X/云途 | M16: XX
A17: =D17&E17 -> OPPO a56默认 | B17: 手机 | C17: OPPO | D17: OPPO a56 | E17: 默认 | G17: / | I17: 16 | K17: 线下 | L17: X/汇租机 | M17: YY
A18: =D18&E18 -> oppo a8默认 | B18: 手机 | C18: OPPO | D18: oppo a8 | E18: 默认 | G18: / | I18: 17 | K18: 线下 | L18: X/租机乐
A19: =D19&E19 -> OPPO R11P默认 | B19: 手机 | C19: OPPO | D19: OPPO R11P | E19: 默认 | G19: 170 | I19: 18 | K19: 线下 | L19: X/倬石
A20: =D20&E20 -> OPPO R17PRO默认 | B20: 手机 | C20: OPPO | D20: OPPO R17PRO | E20: 默认 | G20: / | I20: 19
A21: =D21&E21 -> OPPO r9默认 | B21: 手机 | C21: OPPO | D21: OPPO r9 | E21: 默认 | G21: 100 | I21: 20
A22: =D22&E22 -> OPPO Reno13 Pro默认 | B22: 手机 | C22: OPPO | D22: OPPO Reno13 Pro | E22: 默认 | G22: / | I22: 21
A23: =D23&E23 -> OPPOA1X默认 | B23: 手机 | C23: OPPO | D23: OPPOA1X | E23: 默认 | G23: / | I23: 22
A24: =D24&E24 -> OPPOA5默认 | B24: 手机 | C24: OPPO | D24: OPPOA5 | E24: 默认 | G24: / | I24: 23
A25: =D25&E25 -> OPPOA53默认 | B25: 手机 | C25: OPPO | D25: OPPOA53 | E25: 默认 | G25: 280 | I25: 24
A26: =D26&E26 -> OPPOA57默认 | B26: 手机 | C26: OPPO | D26: OPPOA57 | E26: 默认 | G26: 310 | I26: 25
A27: =D27&E27 -> OPPOA58默认 | B27: 手机 | C27: OPPO | D27: OPPOA58 | E27: 默认 | G27: /
A28: =D28&E28 -> OPPOA58x默认 | B28: 手机 | C28: OPPO | D28: OPPOA58x | E28: 默认 | G28: /
A29: =D29&E29 -> OPPOA72默认 | B29: 手机 | C29: OPPO | D29: OPPOA72 | E29: 默认 | G29: 290
A30: =D30&E30 -> OPPOA92s默认 | B30: 手机 | C30: OPPO | D30: OPPOA92s | E30: 默认 | G30: 290
A31: =D31&E31 -> OPPOA92S 5G默认 | B31: 手机 | C31: OPPO | D31: OPPOA92S 5G | E31: 默认 | G31: 290
A32: =D32&E32 -> OPPOA96默认 | B32: 手机 | C32: OPPO | D32: OPPOA96 | E32: 默认 | G32: /
A33: =D33&E33 -> OPPOA97默认 | B33: 手机 | C33: OPPO | D33: OPPOA97 | E33: 默认 | G33: /
A34: =D34&E34 -> OPPOK5默认 | B34: 手机 | C34: OPPO | D34: OPPOK5 | E34: 默认 | G34: /
A35: =D35&E35 -> OPPOK9默认 | B35: 手机 | C35: OPPO | D35: OPPOK9 | E35: 默认 | G35: /
A36: =D36&E36 -> OPPOR11默认 | B36: 手机 | C36: OPPO | D36: OPPOR11 | E36: 默认 | G36: 170
A37: =D37&E37 -> OPPOR15默认 | B37: 手机 | C37: OPPO | D37: OPPOR15 | E37: 默认 | G37: 190
A38: =D38&E38 -> OPPOR17默认 | B38: 手机 | C38: OPPO | D38: OPPOR17 | E38: 默认 | G38: 230
A39: =D39&E39 -> OPPOReno13默认 | B39: 手机 | C39: OPPO | D39: OPPOReno13 | E39: 默认 | G39: /
A40: =D40&E40 -> OPPOReno4默认 | B40: 手机 | C40: OPPO | D40: OPPOReno4 | E40: 默认 | G40: 270
...

Sheet 订单明细
A1: 序号 | B1: 日期 | C1: 订单来源 | D1: 订单属性 | E1: 订单类型 | F1: 销售渠道 | G1: 人员 | H1: 渠道类别 | I1: 网店订单号 | J1: 客户名称 | K1: 品牌 | L1: 货品名称 | M1: 规格 | N1: 数量 | O1: 单价 | P1: 金额 | Q1: 收款账户 | R1: 物流单号 | S1: 收/发货人 | T1: 订单状态 | U1: 客服备注 | V1: 转租赁2 货品名称 | W1: 转租赁2 规格 | X1: 已交租期 | Y1: 已交租金
A2: =IF(B2="","-",ROW(A1)) -> 1 | B2: 46174 | C2: 新增 | D2: 租赁1 | E2: 新增业务 | F2: 租机乐 | G2: YY | H2: =_xlfn.XLOOKUP(F2,产品资料!L:L,产品资料!K:K) -> 平台 | I2: ME20260601095925060029 | J2: 张影 | K2: =_xlfn.XLOOKUP(L2,产品资料!D:D,产品资料!C:C) -> 苹果 | L2: 苹果12 | M2: 128G | N2: 3 | P2: =N2*O2 -> 0 | R2: SF1555013558828 | S2: 张影 | T2: 已发货
A3: =IF(B3="","-",ROW(A2)) -> 2 | B3: 46174 | C3: 新增 | D3: 租赁1 | E3: 新增业务 | F3: 租机乐 | G3: YY | H3: =_xlfn.XLOOKUP(F3,产品资料!L:L,产品资料!K:K) -> 平台 | I3: ME20260530121755122204 | J3: 屈孝龙 | K3: =_xlfn.XLOOKUP(L3,产品资料!D:D,产品资料!C:C) -> 苹果 | L3: 苹果7 | M3: 默认 | N3: 10 | P3: =N3*O3 -> 0 | R3: SF1555013558855 | S3: 屈孝龙 | T3: 已发货 | U3: 发回单号SF0211562923799
A4: =IF(B4="","-",ROW(A3)) -> 3 | B4: 46174 | C4: 新增 | D4: 租赁1 | E4: 新增业务 | F4: 汇租机 | G4: YY | H4: =_xlfn.XLOOKUP(F4,产品资料!L:L,产品资料!K:K) -> 平台 | I4: ME20251128153744642226 | J4: 佟立衣 | K4: =_xlfn.XLOOKUP(L4,产品资料!D:D,产品资料!C:C) -> 无 | L4: 续期租金 | M4: 默认 | N4: 1 | O4: 110 | P4: =N4*O4 -> 110 | Q4: YY微信 | R4: -- | S4: 佟立衣 | T4: --
A5: =IF(B5="","-",ROW(A4)) -> 4 | B5: 46174 | C5: 新增 | D5: 租赁1 | E5: 新增业务 | F5: 租机乐 | G5: YY | H5: =_xlfn.XLOOKUP(F5,产品资料!L:L,产品资料!K:K) -> 平台 | I5: ME20260507154804059202 | J5: 胡瑜 | K5: =_xlfn.XLOOKUP(L5,产品资料!D:D,产品资料!C:C) -> 无 | L5: 续期租金 | M5: 默认 | N5: 1 | O5: 675 | P5: =N5*O5 -> 675 | Q5: YY支付宝 | R5: -- | S5: 胡瑜 | T5: --
A6: =IF(B6="","-",ROW(A5)) -> 5 | B6: 46174 | C6: 新增 | D6: 租赁1 | E6: 新增业务 | F6: 极客矩阵 | G6: YY | H6: =_xlfn.XLOOKUP(F6,产品资料!L:L,产品资料!K:K) -> 平台 | I6: ME20260308155704546442 | J6: 张文 | K6: =_xlfn.XLOOKUP(L6,产品资料!D:D,产品资料!C:C) -> 无 | L6: 续期租金 | M6: 默认 | N6: 1 | O6: 80 | P6: =N6*O6 -> 80 | Q6: YY微信 | R6: -- | S6: 张文 | T6: --
A7: =IF(B7="","-",ROW(A6)) -> 6 | B7: 46174 | C7: 新增 | D7: 租赁1 | E7: 新增业务 | F7: 极客矩阵 | G7: YY | H7: =_xlfn.XLOOKUP(F7,产品资料!L:L,产品资料!K:K) -> 平台 | I7: ME20260226150759428196，ME20260226150702786060 | J7: 于加媛 | K7: =_xlfn.XLOOKUP(L7,产品资料!D:D,产品资料!C:C) -> 无 | L7: 续期租金 | M7: 默认 | N7: 1 | O7: 1900 | P7: =N7*O7 -> 1900 | Q7: YY微信 | R7: -- | S7: 于加媛 | T7: --
A8: =IF(B8="","-",ROW(A7)) -> 7 | B8: 46174 | C8: 新增 | D8: 租赁1 | E8: 新增业务 | F8: 云界互联 | G8: YY | H8: =_xlfn.XLOOKUP(F8,产品资料!L:L,产品资料!K:K) -> 平台 | I8: ME20260227200618443247 | J8: 彭屿珊 | K8: =_xlfn.XLOOKUP(L8,产品资料!D:D,产品资料!C:C) -> 无 | L8: 续期租金 | M8: 默认 | N8: 1 | O8: 560 | P8: =N8*O8 -> 560 | Q8: YY微信 | R8: -- | S8: 彭屿珊 | T8: --
A9: =IF(B9="","-",ROW(A8)) -> 8 | B9: 46174 | C9: 新增 | D9: 租赁1 | E9: 新增业务 | F9: 倬石电子 | G9: YY | H9: =_xlfn.XLOOKUP(F9,产品资料!L:L,产品资料!K:K) -> 平台 | I9: ME20260326161940292813 | J9: 叶慧鸿 | K9: =_xlfn.XLOOKUP(L9,产品资料!D:D,产品资料!C:C) -> 无 | L9: 续期租金 | M9: 默认 | N9: 1 | O9: 800 | P9: =N9*O9 -> 800 | Q9: YY微信 | R9: -- | S9: 叶慧鸿 | T9: --
A10: =IF(B10="","-",ROW(A9)) -> 9 | B10: 46174 | C10: 新增 | D10: 租赁1 | E10: 新增业务 | F10: 极客矩阵 | G10: YY | H10: =_xlfn.XLOOKUP(F10,产品资料!L:L,产品资料!K:K) -> 平台 | I10: ME20260209143504886489 | J10: 杨江朝 | K10: =_xlfn.XLOOKUP(L10,产品资料!D:D,产品资料!C:C) -> 无 | L10: 续期租金 | M10: 默认 | N10: 1 | O10: 605 | P10: =N10*O10 -> 605 | Q10: YY微信 | R10: -- | S10: 杨江朝 | T10: --
A11: =IF(B11="","-",ROW(A10)) -> 10 | B11: 46174 | C11: 新增 | D11: 租赁1 | E11: 新增业务 | F11: 云界互联 | G11: YY | H11: =_xlfn.XLOOKUP(F11,产品资料!L:L,产品资料!K:K) -> 平台 | I11: ME20260228145733173649 | J11: 巢文成 | K11: =_xlfn.XLOOKUP(L11,产品资料!D:D,产品资料!C:C) -> 无 | L11: 续期租金 | M11: 默认 | N11: 1 | O11: 200 | P11: =N11*O11 -> 200 | Q11: YY微信 | R11: -- | S11: 巢文成 | T11: --
A12: =IF(B12="","-",ROW(A11)) -> 11 | B12: 46174 | C12: 新增 | D12: 租赁1 | E12: 新增业务 | F12: 租机乐 | G12: YY | H12: =_xlfn.XLOOKUP(F12,产品资料!L:L,产品资料!K:K) -> 平台 | I12: ME20260530121755122204 | J12: 屈孝龙 | K12: =_xlfn.XLOOKUP(L12,产品资料!D:D,产品资料!C:C) -> 无 | L12: 续期租金 | M12: 默认 | N12: 1 | O12: 100 | P12: =N12*O12 -> 100 | Q12: YY微信 | R12: -- | S12: 屈孝龙 | T12: --
A13: =IF(B13="","-",ROW(A12)) -> 12 | B13: 46174 | C13: 新增 | D13: 租赁2 | E13: 新增业务 | F13: 倬石电子 | G13: YY | H13: =_xlfn.XLOOKUP(F13,产品资料!L:L,产品资料!K:K) -> 平台 | I13: ME20260424190540868024 | J13: 冯淑辉 | K13: =_xlfn.XLOOKUP(L13,产品资料!D:D,产品资料!C:C) -> 无 | L13: 全部转租赁2 | M13: 默认 | N13: 6 | O13: 450 | P13: =N13*O13 -> 2700 | Q13: YY支付宝 | R13: -- | S13: 冯淑辉 | T13: -- | V13: 小米10 | W13: 默认 | X13: 1 | Y13: 300
A14: =IF(B14="","-",ROW(A13)) -> 13 | B14: 46174 | C14: 新增 | D14: 租赁2 | E14: 新增业务 | F14: 云途 | G14: XX | H14: =_xlfn.XLOOKUP(F14,产品资料!L:L,产品资料!K:K) -> 平台 | I14: ME20260601162843205367 | J14: 冯林浩 | K14: =_xlfn.XLOOKUP(L14,产品资料!D:D,产品资料!C:C) -> OPPO | L14: OPPOA72 | M14: 默认 | N14: 3 | P14: =N14*O14 -> 0 | S14: 冯林浩 | T14: 未发货
A15: =IF(B15="","-",ROW(A14)) -> 14 | B15: 46174 | C15: 新增 | D15: 租赁2 | E15: 新增业务 | F15: 云途 | G15: XX | H15: =_xlfn.XLOOKUP(F15,产品资料!L:L,产品资料!K:K) -> 平台 | I15: ME20260601210045848198 | J15: 贾亮亮 | K15: =_xlfn.XLOOKUP(L15,产品资料!D:D,产品资料!C:C) -> OPPO | L15: OPPOK9 | M15: 默认 | N15: 10 | P15: =N15*O15 -> 0 | S15: 贾亮亮 | T15: 未发货
A16: =IF(B16="","-",ROW(A15)) -> 15 | B16: 46174 | C16: 新增 | D16: 租赁1 | E16: 新增业务 | G16: XX | H16: =_xlfn.XLOOKUP(F16,产品资料!L:L,产品资料!K:K) -> 0 | I16: ME20260327121542586258/ME20260327121542586258 | J16: 李婷婷 | K16: =_xlfn.XLOOKUP(L16,产品资料!D:D,产品资料!C:C) -> 无 | L16: 续期租金 | M16: 默认 | N16: 1 | O16: 360 | P16: =N16*O16 -> 360 | Q16: XX微信
A17: =IF(B17="","-",ROW(A16)) -> - | H17: =_xlfn.XLOOKUP(F17,产品资料!L:L,产品资料!K:K) -> 0 | K17: =_xlfn.XLOOKUP(L17,产品资料!D:D,产品资料!C:C) -> 0 | P17: =N17*O17 -> 0
A18: =IF(B18="","-",ROW(A17)) -> - | H18: =_xlfn.XLOOKUP(F18,产品资料!L:L,产品资料!K:K) -> 0 | K18: =_xlfn.XLOOKUP(L18,产品资料!D:D,产品资料!C:C) -> 0 | P18: =N18*O18 -> 0
A19: =IF(B19="","-",ROW(A18)) -> - | H19: =_xlfn.XLOOKUP(F19,产品资料!L:L,产品资料!K:K) -> 0 | K19: =_xlfn.XLOOKUP(L19,产品资料!D:D,产品资料!C:C) -> 0 | P19: =N19*O19 -> 0
A20: =IF(B20="","-",ROW(A19)) -> - | H20: =_xlfn.XLOOKUP(F20,产品资料!L:L,产品资料!K:K) -> 0 | K20: =_xlfn.XLOOKUP(L20,产品资料!D:D,产品资料!C:C) -> 0 | P20: =N20*O20 -> 0
A21: =IF(B21="","-",ROW(A20)) -> - | H21: =_xlfn.XLOOKUP(F21,产品资料!L:L,产品资料!K:K) -> 0 | K21: =_xlfn.XLOOKUP(L21,产品资料!D:D,产品资料!C:C) -> 0 | P21: =N21*O21 -> 0
A22: =IF(B22="","-",ROW(A21)) -> - | H22: =_xlfn.XLOOKUP(F22,产品资料!L:L,产品资料!K:K) -> 0 | K22: =_xlfn.XLOOKUP(L22,产品资料!D:D,产品资料!C:C) -> 0 | P22: =N22*O22 -> 0
A23: =IF(B23="","-",ROW(A22)) -> - | H23: =_xlfn.XLOOKUP(F23,产品资料!L:L,产品资料!K:K) -> 0 | K23: =_xlfn.XLOOKUP(L23,产品资料!D:D,产品资料!C:C) -> 0 | P23: =N23*O23 -> 0
A24: =IF(B24="","-",ROW(A23)) -> - | H24: =_xlfn.XLOOKUP(F24,产品资料!L:L,产品资料!K:K) -> 0 | K24: =_xlfn.XLOOKUP(L24,产品资料!D:D,产品资料!C:C) -> 0 | P24: =N24*O24 -> 0
A25: =IF(B25="","-",ROW(A24)) -> - | H25: =_xlfn.XLOOKUP(F25,产品资料!L:L,产品资料!K:K) -> 0 | K25: =_xlfn.XLOOKUP(L25,产品资料!D:D,产品资料!C:C) -> 0 | P25: =N25*O25 -> 0
A26: =IF(B26="","-",ROW(A25)) -> - | H26: =_xlfn.XLOOKUP(F26,产品资料!L:L,产品资料!K:K) -> 0 | K26: =_xlfn.XLOOKUP(L26,产品资料!D:D,产品资料!C:C) -> 0 | P26: =N26*O26 -> 0
A27: =IF(B27="","-",ROW(A26)) -> - | H27: =_xlfn.XLOOKUP(F27,产品资料!L:L,产品资料!K:K) -> 0 | K27: =_xlfn.XLOOKUP(L27,产品资料!D:D,产品资料!C:C) -> 0 | P27: =N27*O27 -> 0
A28: =IF(B28="","-",ROW(A27)) -> - | H28: =_xlfn.XLOOKUP(F28,产品资料!L:L,产品资料!K:K) -> 0 | K28: =_xlfn.XLOOKUP(L28,产品资料!D:D,产品资料!C:C) -> 0 | P28: =N28*O28 -> 0
... A123: =IF(B123="","-",ROW(A122)) -> - | H123: =_xlfn.XLOOKUP(F123,产品资料!L:L,产品资料!K:K) -> 0 | K123: =_xlfn.XLOOKUP(L123,产品资料!D:D,产品资料!C:C) -> 0 | P123: =N123*O123 -> 0

Sheet 填写要求
A1: 项目 | B1: 内容 | C1: 备注
A2: 订单来源 | B2: 新增/服务 | C2: 设置了有效性，可以直接选
A3: 出库属性 | B3: 租赁1/租赁2 | C3: 设置了有效性，可以直接选
A4: 销售渠道 | B4: 肯定都有渠道的，尤其是租后服务，是原订单的渠道 | C4: 设置了有效性，可以直接选
A5: 渠道类型 | B5: 公式，不要填， | C5: 自动生成
A6: 网店订单号 | B6: 渠道类型是平台，就要填，
A7: 客户名 | B7: 要填，这是基本信息
A8: 产品信息 | B8: 删除货品编号，填货品名称+规格，一行只能填一种产品+1种规格 | C8: 设置了有效性，可以直接选
A9: 数量/单价 | B9: 必填项，没有金额就填0
A10: 金额 | B10: 公式，不要填， | C10: 自动生成
A11: 收货人 | B11: 要填，这是基本信息
A12: 物流单号 | B12: 物流单号要填，租后跟进，找仓库告知物流单号
A13: 订单状态 | B13: 需要发货的，发货后填“已发货”，不需要发货的，填“不用发货”、退货的，填“已退回”
